Workbook
Name Slicer_1st_Level: #REF!
Name Slicer_2nd_Level: #REF!
Name Slicer_3d_Level: #REF!

Sheet  Follow Up 1st
A1: No | B1: Name | C1: Class | D1: Week 1 | H1: Week 2 | L1: Week 3 | P1: Week 4 | T1: Week 5 | X1: Week 6 | AB1: Week 7 | AF1: Week 8 | AJ1: Week 9 | AN1: Week 10 | AR1: Week 11 | AV1: Week 12 | AZ1: Week 13 | BD1: Week 14 | BH1: Week 15 | BL1: Week 16 | BP1: Week 17 | BT1: Week 18 | BX1: Week 19 | CB1: Quiz1 | CC1: Quiz2 | CD1: Chapter | CE1: Chapter | CF1: Portfolio | CG1: First Term Average
D2: Attendance (5) | E2: Participation | F2: Behavior | G2: Homework (5) | H2: Attendance (5) | I2: Participation | J2: Behavior | K2: Homework (5) | L2: Attendance (5) | M2: Participation | N2: Behavior | O2: Homework (5) | P2: Attendance (5) | Q2: Participation | R2: Behavior | S2: Homework (5) | T2: Attendance (5) | U2: Participation | V2: Behavior | W2: Homework (5) | X2: Attendance (5) | Y2: Participation | Z2: Behavior | AA2: Homework (5) | AB2: Attendance (5) | AC2: Participation | AD2: Behavior | AE2: Homework (5) | AF2: Attendance (5) | AG2: Participation | AH2: Behavior | AI2: Homework (5) | AJ2: Attendance (5) | AK2: Participation | AL2: Behavior | AM2: Homework (5) | AN2: Attendance (5) | AO2: Participation | AP2: Behavior | AQ2: Homework (5) | AR2: Attendance (5) | AS2: Participation | AT2: Behavior | AU2: Homework (5) | AV2: Attendance (5) | AW2: Participation | AX2: Behavior | AY2: Homework (5) | AZ2: Attendance (5) | BA2: Participation | BB2: Behavior | BC2: Homework (5) | BD2: Attendance (5) | BE2: Participation | BF2: Behavior | BG2: Homework (5) | BH2: Attendance (5) | BI2: Participation | BJ2: Behavior | BK2: Homework (5) | BL2: Attendance (5) | BM2: Participation | BN2: Behavior | BO2: Homework (5) | BP2: Attendance (5) | BQ2: Participation | BR2: Behavior | BS2: Homework (5) | BT2: Attendance (5) | BU2: Participation | BV2: Behavior | BW2: Homework (5) | BX2: Attendance (5) | BY2: Participation | BZ2: Behavior | CA2: Homework (5) | CB2: 5 | CC2: 5 | CD2: Test (1) 10 | CE2: Test (2) 10 | CF2: 5 | CG2: Attendance (5) | CH2: Participation | CI2: Behavior | CJ2: Homework (5) | CK2: Quiz (5) | CL2: Chapter Test (10) | CM2: Portfolio (5)
A3: 1 | B3: EBRAHIM NASSER ABDULLAH ALSAGER | C3: 4A | D3: 5 | E3: 5 | F3: 5 | G3: 5 | H3: 5 | I3: 5 | J3: 5 | K3: 5 | L3: 5 | M3: 5 | N3: 5 | O3: 5 | P3: 5 | Q3: 5 | R3: 5 | S3: 5 | T3: 5 | U3: 5 | V3: 5 | W3: 5 | X3: 5 | Y3: 5 | Z3: 5 | AA3: 5 | AB3: 5 | AC3: 5 | AD3: 5 | AE3: 5 | AF3: 5 | AG3: 5 | AH3: 5 | AI3: 5 | AJ3: 5 | AK3: 5 | AL3: 5 | AM3: 5 | AN3: 5 | AO3: 5 | AP3: 5 | AQ3: 5 | AR3: 5 | AS3: 5 | AT3: 5 | AU3: 5 | CB3: 45693 | CD3: 5 | CF3: 5 | CG3: =AVERAGE(BX3,BT3,BP3,BL3,BH3,BD3,AZ3,AV3,AR3,AN3,AJ3,AF3,AB3,X3,T3,P3,L3,H3,D3) -> 5 | CH3: =AVERAGE(BY3,BU3,BQ3,BM3,BI3,BE3,BA3,AW3,AS3,AO3,AK3,AG3,AC3,Y3,U3,Q3,M3,I3,E3) -> 5 | CI3: =AVERAGE(BZ3,BV3,BR3,BN3,BJ3,BF3,BB3,AX3,AT3,AP3,AL3,AH3,AD3,Z3,V3,R3,N3,J3,F3) -> 5 | CJ3: =AVERAGE(CA3,BW3,BS3,BO3,BK3,BG3,BC3,AY3,AU3,AQ3,AM3,AI3,AE3,AA3,W3,S3,O3,K3,G3) -> 5 | CK3: =(' Follow Up 1st'!$CB3+' Follow Up 1st'!$CC3)/2 -> 22846.5 | CL3: =(' Follow Up 1st'!$CD3+' Follow Up 1st'!$CE3)/2 -> 2.5 | CM3: 5
A4: 2 | B4: SAIF KHALID MOHAMMED ALAFALIQ | C4: 4A | D4: 5 | E4: 5 | F4: 5 | G4: 5 | H4: 5 | I4: 5 | J4: 5 | K4: 5 | L4: 5 | M4: 5 | N4: 5 | O4: 5 | P4: 5 | Q4: 5 | R4: 5 | S4: 5 | T4: 5 | U4: 5 | V4: 5 | W4: 5 | X4: 5 | Y4: 5 | Z4: 5 | AA4: 5 | AB4: 5 | AC4: 5 | AD4: 5 | AE4: 5 | AF4: 5 | AG4: 5 | AH4: 5 | AI4: 5 | AJ4: 5 | AK4: 5 | AL4: 5 | AM4: 5 | AN4: 5 | AO4: 5 | AP4: 5 | AQ4: 5 | AR4: 5 | AS4: 5 | AT4: 5 | AU4: 5 | CB4: 5 | CD4: 45843 | CF4: 5 | CG4: =AVERAGE(BX4,BT4,BP4,BL4,BH4,BD4,AZ4,AV4,AR4,AN4,AJ4,AF4,AB4,X4,T4,P4,L4,H4,D4) -> 5 | CH4: =AVERAGE(BY4,BU4,BQ4,BM4,BI4,BE4,BA4,AW4,AS4,AO4,AK4,AG4,AC4,Y4,U4,Q4,M4,I4,E4) -> 5 | CI4: =AVERAGE(BZ4,BV4,BR4,BN4,BJ4,BF4,BB4,AX4,AT4,AP4,AL4,AH4,AD4,Z4,V4,R4,N4,J4,F4) -> 5 | CJ4: =AVERAGE(CA4,BW4,BS4,BO4,BK4,BG4,BC4,AY4,AU4,AQ4,AM4,AI4,AE4,AA4,W4,S4,O4,K4,G4) -> 5 | CK4: =(' Follow Up 1st'!$CB4+' Follow Up 1st'!$CC4)/2 -> 2.5 | CL4: =(' Follow Up 1st'!$CD4+' Follow Up 1st'!$CE4)/2 -> 22921.5 | CM4: 5
A5: 3 | B5: ABBAS ALAA HASSAN AL AITHAN | C5: 4A | D5: 5 | E5: 5 | F5: 5 | G5: 5 | H5: 5 | I5: 5 | J5: 5 | K5: 5 | L5: 5 | M5: 5 | N5: 5 | O5: 5 | P5: 5 | Q5: 5 | R5: 5 | S5: 5 | T5: 5 | U5: 5 | V5: 5 | W5: 5 | X5: 5 | Y5: 5 | Z5: 5 | AA5: 5 | AB5: 5 | AC5: 5 | AD5: 5 | AE5: 5 | AF5: 5 | AG5: 5 | AH5: 5 | AI5: 5 | AJ5: 5 | AK5: 5 | AL5: 5 | AM5: 5 | AN5: 5 | AO5: 5 | AP5: 5 | AQ5: 5 | AR5: 5 | AS5: 5 | AT5: 5 | AU5: 5 | CB5: 5 | CD5: 45813 | CF5: 5 | CG5: =AVERAGE(BX5,BT5,BP5,BL5,BH5,BD5,AZ5,AV5,AR5,AN5,AJ5,AF5,AB5,X5,T5,P5,L5,H5,D5) -> 5 | CH5: =AVERAGE(BY5,BU5,BQ5,BM5,BI5,BE5,BA5,AW5,AS5,AO5,AK5,AG5,AC5,Y5,U5,Q5,M5,I5,E5) -> 5 | CI5: =AVERAGE(BZ5,BV5,BR5,BN5,BJ5,BF5,BB5,AX5,AT5,AP5,AL5,AH5,AD5,Z5,V5,R5,N5,J5,F5) -> 5 | CJ5: =AVERAGE(CA5,BW5,BS5,BO5,BK5,BG5,BC5,AY5,AU5,AQ5,AM5,AI5,AE5,AA5,W5,S5,O5,K5,G5) -> 5 | CK5: =(' Follow Up 1st'!$CB5+' Follow Up 1st'!$CC5)/2 -> 2.5 | CL5: =(' Follow Up 1st'!$CD5+' Follow Up 1st'!$CE5)/2 -> 22906.5 | CM5: 5
A6: 4 | B6: ABDULRAHMAN FAHAD ABDULRAHMAN ALJAMAAN | C6: 4A | D6: 5 | E6: 5 | F6: 5 | G6: 5 | H6: 5 | I6: 5 | J6: 5 | K6: 5 | L6: 5 | M6: 5 | N6: 5 | O6: 5 | P6: 5 | Q6: 5 | R6: 5 | S6: 5 | T6: 5 | U6: 5 | V6: 5 | W6: 5 | X6: 5 | Y6: 5 | Z6: 5 | AA6: 5 | AB6: 5 | AC6: 5 | AD6: 5 | AE6: 5 | AF6: 5 | AG6: 5 | AH6: 5 | AI6: 5 | AJ6: 5 | AK6: 5 | AL6: 5 | AM6: 5 | AN6: 5 | AO6: 5 | AP6: 5 | AQ6: 5 | AR6: 5 | AS6: 5 | AT6: 5 | AU6: 5 | CB6: 45752 | CD6: 5 | CF6: 5 | CG6: =AVERAGE(BX6,BT6,BP6,BL6,BH6,BD6,AZ6,AV6,AR6,AN6,AJ6,AF6,AB6,X6,T6,P6,L6,H6,D6) -> 5 | CH6: =AVERAGE(BY6,BU6,BQ6,BM6,BI6,BE6,BA6,AW6,AS6,AO6,AK6,AG6,AC6,Y6,U6,Q6,M6,I6,E6) -> 5 | CI6: =AVERAGE(BZ6,BV6,BR6,BN6,BJ6,BF6,BB6,AX6,AT6,AP6,AL6,AH6,AD6,Z6,V6,R6,N6,J6,F6) -> 5 | CJ6: =AVERAGE(CA6,BW6,BS6,BO6,BK6,BG6,BC6,AY6,AU6,AQ6,AM6,AI6,AE6,AA6,W6,S6,O6,K6,G6) -> 5 | CK6: =(' Follow Up 1st'!$CB6+' Follow Up 1st'!$CC6)/2 -> 22876 | CL6: =(' Follow Up 1st'!$CD6+' Follow Up 1st'!$CE6)/2 -> 2.5 | CM6: 5
A7: 5 | B7: Abdullah Abdulmajid Alarfaj | C7: 4A | D7: 5 | E7: 5 | F7: 5 | G7: 5 | H7: 5 | I7: 5 | J7: 5 | K7: 5 | L7: 5 | M7: 5 | N7: 5 | O7: 5 | P7: 5 | Q7: 5 | R7: 5 | S7: 5 | T7: 5 | U7: 5 | V7: 5 | W7: 5 | X7: 5 | Y7: 5 | Z7: 5 | AA7: 5 | AB7: 5 | AC7: 5 | AD7: 5 | AE7: 5 | AF7: 5 | AG7: 5 | AH7: 5 | AI7: 5 | AJ7: 5 | AK7: 5 | AL7: 5 | AM7: 5 | AN7: 5 | AO7: 5 | AP7: 5 | AQ7: 5 | AR7: 5 | AS7: 5 | AT7: 5 | AU7: 5 | CB7: 4 | CD7: 9 | CF7: 5 | CG7: =AVERAGE(BX7,BT7,BP7,BL7,BH7,BD7,AZ7,AV7,AR7,AN7,AJ7,AF7,AB7,X7,T7,P7,L7,H7,D7) -> 5 | CH7: =AVERAGE(BY7,BU7,BQ7,BM7,BI7,BE7,BA7,AW7,AS7,AO7,AK7,AG7,AC7,Y7,U7,Q7,M7,I7,E7) -> 5 | CI7: =AVERAGE(BZ7,BV7,BR7,BN7,BJ7,BF7,BB7,AX7,AT7,AP7,AL7,AH7,AD7,Z7,V7,R7,N7,J7,F7) -> 5 | CJ7: =AVERAGE(CA7,BW7,BS7,BO7,BK7,BG7,BC7,AY7,AU7,AQ7,AM7,AI7,AE7,AA7,W7,S7,O7,K7,G7) -> 5 | CK7: =(' Follow Up 1st'!$CB7+' Follow Up 1st'!$CC7)/2 -> 2 | CL7: =(' Follow Up 1st'!$CD7+' Follow Up 1st'!$CE7)/2 -> 4.5 | CM7: 5
A8: 6 | B8: OMAR SHADI MOHAMMAD QAWAQNEH | C8: 4A | D8: 5 | E8: 5 | F8: 5 | G8: 5 | H8: 5 | I8: 5 | J8: 5 | K8: 5 | L8: 5 | M8: 5 | N8: 5 | O8: 5 | P8: 5 | Q8: 5 | R8: 5 | S8: 5 | T8: 5 | U8: 5 | V8: 5 | W8: 5 | X8: 5 | Y8: 5 | Z8: 5 | AA8: 5 | AB8: 5 | AC8: 5 | AD8: 5 | AE8: 5 | AF8: 5 | AG8: 5 | AH8: 5 | AI8: 5 | AJ8: 5 | AK8: 5 | AL8: 5 | AM8: 5 | AN8: 5 | AO8: 5 | AP8: 5 | AQ8: 5 | AR8: 5 | AS8: 5 | AT8: 5 | AU8: 5 | CB8: 5 | CD8: 45843 | CF8: 5 | CG8: =AVERAGE(BX8,BT8,BP8,BL8,BH8,BD8,AZ8,AV8,AR8,AN8,AJ8,AF8,AB8,X8,T8,P8,L8,H8,D8) -> 5 | CH8: =AVERAGE(BY8,BU8,BQ8,BM8,BI8,BE8,BA8,AW8,AS8,AO8,AK8,AG8,AC8,Y8,U8,Q8,M8,I8,E8) -> 5 | CI8: =AVERAGE(BZ8,BV8,BR8,BN8,BJ8,BF8,BB8,AX8,AT8,AP8,AL8,AH8,AD8,Z8,V8,R8,N8,J8,F8) -> 5 | CJ8: =AVERAGE(CA8,BW8,BS8,BO8,BK8,BG8,BC8,AY8,AU8,AQ8,AM8,AI8,AE8,AA8,W8,S8,O8,K8,G8) -> 5 | CK8: =(' Follow Up 1st'!$CB8+' Follow Up 1st'!$CC8)/2 -> 2.5 | CL8: =(' Follow Up 1st'!$CD8+' Follow Up 1st'!$CE8)/2 -> 22921.5 | CM8: 5
A9: 7 | B9: FAISAL ABDULMOHSEN ABDULAZIZ ALMULHEM | C9: 4A | D9: 5 | E9: 5 | F9: 5 | G9: 5 | H9: 5 | I9: 5 | J9: 5 | K9: 5 | L9: 5 | M9: 5 | N9: 5 | O9: 5 | P9: 5 | Q9: 5 | R9: 5 | S9: 5 | T9: 5 | U9: 5 | V9: 5 | W9: 5 | X9: 5 | Y9: 5 | Z9: 5 | AA9: 5 | AB9: 5 | AC9: 5 | AD9: 5 | AE9: 5 | AF9: 5 | AG9: 5 | AH9: 5 | AI9: 5 | AJ9: 5 | AK9: 5 | AL9: 5 | AM9: 5 | AN9: 5 | AO9: 5 | AP9: 5 | AQ9: 5 | AR9: 5 | AS9: 5 | AT9: 5 | AU9: 5 | CB9: 5 | CD9: 9 | CF9: 5 | CG9: =AVERAGE(BX9,BT9,BP9,BL9,BH9,BD9,AZ9,AV9,AR9,AN9,AJ9,AF9,AB9,X9,T9,P9,L9,H9,D9) -> 5 | CH9: =AVERAGE(BY9,BU9,BQ9,BM9,BI9,BE9,BA9,AW9,AS9,AO9,AK9,AG9,AC9,Y9,U9,Q9,M9,I9,E9) -> 5 | CI9: =AVERAGE(BZ9,BV9,BR9,BN9,BJ9,BF9,BB9,AX9,AT9,AP9,AL9,AH9,AD9,Z9,V9,R9,N9,J9,F9) -> 5 | CJ9: =AVERAGE(CA9,BW9,BS9,BO9,BK9,BG9,BC9,AY9,AU9,AQ9,AM9,AI9,AE9,AA9,W9,S9,O9,K9,G9) -> 5 | CK9: =(' Follow Up 1st'!$CB9+' Follow Up 1st'!$CC9)/2 -> 2.5 | CL9: =(' Follow Up 1st'!$CD9+' Follow Up 1st'!$CE9)/2 -> 4.5 | CM9: 5
A10: 8 | B10: MOHAMMED AHMED YOUSIF ALYOUSIF | C10: 4A | D10: 5 | E10: 5 | F10: 5 | G10: 5 | H10: 5 | I10: 5 | J10: 5 | K10: 5 | L10: 5 | M10: 5 | N10: 5 | O10: 5 | P10: 5 | Q10: 5 | R10: 5 | S10: 5 | T10: 5 | U10: 5 | V10: 5 | W10: 5 | X10: 5 | Y10: 5 | Z10: 5 | AA10: 5 | AB10: 5 | AC10: 5 | AD10: 5 | AE10: 5 | AF10: 5 | AG10: 5 | AH10: 5 | AI10: 5 | AJ10: 5 | AK10: 5 | AL10: 5 | AM10: 5 | AN10: 5 | AO10: 5 | AP10: 5 | AQ10: 5 | AR10: 5 | AS10: 5 | AT10: 5 | AU10: 5 | CB10: 45662 | CD10: 45813 | CF10: 5 | CG10: =AVERAGE(BX10,BT10,BP10,BL10,BH10,BD10,AZ10,AV10,AR10,AN10,AJ10,AF10,AB10,X10,T10,P10,L10,H10,D10) -> 5 | CH10: =AVERAGE(BY10,BU10,BQ10,BM10,BI10,BE10,BA10,AW10,AS10,AO10,AK10,AG10,AC10,Y10,U10,Q10,M10,I10,E10) -> 5 | CI10: =AVERAGE(BZ10,BV10,BR10,BN10,BJ10,BF10,BB10,AX10,AT10,AP10,AL10,AH10,AD10,Z10,V10,R10,N10,J10,F10) -> 5 | CJ10: =AVERAGE(CA10,BW10,BS10,BO10,BK10,BG10,BC10,AY10,AU10,AQ10,AM10,AI10,AE10,AA10,W10,S10,O10,K10,G10) -> 5 | CK10: =(' Follow Up 1st'!$CB10+' Follow Up 1st'!$CC10)/2 -> 22831 | CL10: =(' Follow Up 1st'!$CD10+' Follow Up 1st'!$CE10)/2 -> 22906.5 | CM10: 5
A11: 9 | B11: YOUSIF AHMED ABDULLMAJEED ALHAJII | C11: 4A | D11: 5 | E11: 5 | F11: 5 | G11: 5 | H11: 5 | I11: 5 | J11: 5 | K11: 5 | L11: 5 | M11: 5 | N11: 5 | O11: 5 | P11: 5 | Q11: 5 | R11: 5 | S11: 5 | T11: 5 | U11: 5 | V11: 5 | W11: 5 | X11: 5 | Y11: 5 | Z11: 5 | AA11: 5 | AB11: 5 | AC11: 5 | AD11: 5 | AE11: 5 | AF11: 5 | AG11: 5 | AH11: 5 | AI11: 5 | AJ11: 5 | AK11: 5 | AL11: 5 | AM11: 5 | AN11: 5 | AO11: 5 | AP11: 5 | AQ11: 5 | AR11: 5 | AS11: 5 | AT11: 5 | AU11: 5 | CB11: 5 | CD11: 45905 | CF11: 5 | CG11: =AVERAGE(BX11,BT11,BP11,BL11,BH11,BD11,AZ11,AV11,AR11,AN11,AJ11,AF11,AB11,X11,T11,P11,L11,H11,D11) -> 5 | CH11: =AVERAGE(BY11,BU11,BQ11,BM11,BI11,BE11,BA11,AW11,AS11,AO11,AK11,AG11,AC11,Y11,U11,Q11,M11,I11,E11) -> 5 | CI11: =AVERAGE(BZ11,BV11,BR11,BN11,BJ11,BF11,BB11,AX11,AT11,AP11,AL11,AH11,AD11,Z11,V11,R11,N11,J11,F11) -> 5 | CJ11: =AVERAGE(CA11,BW11,BS11,BO11,BK11,BG11,BC11,AY11,AU11,AQ11,AM11,AI11,AE11,AA11,W11,S11,O11,K11,G11) -> 5 | CK11: =(' Follow Up 1st'!$CB11+' Follow Up 1st'!$CC11)/2 -> 2.5 | CL11: =(' Follow Up 1st'!$CD11+' Follow Up 1st'!$CE11)/2 -> 22952.5 | CM11: 5
A12: 10 | B12: ABDULAZIZ FAHAD ABDULAZIZ ALMULHIM | C12: 4A | D12: 5 | E12: 5 | F12: 5 | G12: 5 | H12: 5 | I12: 5 | J12: 5 | K12: 5 | L12: 5 | M12: 5 | N12: 5 | O12: 5 | P12: 5 | Q12: 5 | R12: 5 | S12: 5 | T12: 5 | U12: 5 | V12: 5 | W12: 5 | X12: 5 | Y12: 5 | Z12: 5 | AA12: 5 | AB12: 5 | AC12: 5 | AD12: 5 | AE12: 5 | AF12: 5 | AG12: 5 | AH12: 5 | AI12: 5 | AJ12: 5 | AK12: 5 | AL12: 5 | AM12: 5 | AN12: 5 | AO12: 5 | AP12: 5 | AQ12: 5 | AR12: 5 | AS12: 5 | AT12: 5 | AU12: 5 | CB12: 5 | CD12: 45843 | CF12: 5 | CG12: =AVERAGE(BX12,BT12,BP12,BL12,BH12,BD12,AZ12,AV12,AR12,AN12,AJ12,AF12,AB12,X12,T12,P12,L12,H12,D12) -> 5 | CH12: =AVERAGE(BY12,BU12,BQ12,BM12,BI12,BE12,BA12,AW12,AS12,AO12,AK12,AG12,AC12,Y12,U12,Q12,M12,I12,E12) -> 5 | CI12: =AVERAGE(BZ12,BV12,BR12,BN12,BJ12,BF12,BB12,AX12,AT12,AP12,AL12,AH12,AD12,Z12,V12,R12,N12,J12,F12) -> 5 | CJ12: =AVERAGE(CA12,BW12,BS12,BO12,BK12,BG12,BC12,AY12,AU12,AQ12,AM12,AI12,AE12,AA12,W12,S12,O12,K12,G12) -> 5 | CK12: =(' Follow Up 1st'!$CB12+' Follow Up 1st'!$CC12)/2 -> 2.5 | CL12: =(' Follow Up 1st'!$CD12+' Follow Up 1st'!$CE12)/2 -> 22921.5 | CM12: 5
A13: 11 | B13: Ali Hussain Alhassan | C13: 4A | D13: 5 | E13: 5 | F13: 5 | G13: 5 | H13: 5 | I13: 5 | J13: 5 | K13: 5 | L13: 5 | M13: 5 | N13: 5 | O13: 5 | P13: 5 | Q13: 5 | R13: 5 | S13: 5 | T13: 5 | U13: 5 | V13: 5 | W13: 5 | X13: 5 | Y13: 5 | Z13: 5 | AA13: 5 | AB13: 5 | AC13: 5 | AD13: 5 | AE13: 5 | AF13: 5 | AG13: 5 | AH13: 5 | AI13: 5 | AJ13: 5 | AK13: 5 | AL13: 5 | AM13: 5 | AN13: 5 | AO13: 5 | AP13: 5 | AQ13: 5 | AR13: 5 | AS13: 5 | AT13: 5 | AU13: 5 | CB13: 5 | CD13: 45843 | CF13: 5 | CG13: =AVERAGE(BX13,BT13,BP13,BL13,BH13,BD13,AZ13,AV13,AR13,AN13,AJ13,AF13,AB13,X13,T13,P13,L13,H13,D13) -> 5 | CH13: =AVERAGE(BY13,BU13,BQ13,BM13,BI13,BE13,BA13,AW13,AS13,AO13,AK13,AG13,AC13,Y13,U13,Q13,M13,I13,E13) -> 5 | CI13: =AVERAGE(BZ13,BV13,BR13,BN13,BJ13,BF13,BB13,AX13,AT13,AP13,AL13,AH13,AD13,Z13,V13,R13,N13,J13,F13) -> 5 | CJ13: =AVERAGE(CA13,BW13,BS13,BO13,BK13,BG13,BC13,AY13,AU13,AQ13,AM13,AI13,AE13,AA13,W13,S13,O13,K13,G13) -> 5 | CK13: =(' Follow Up 1st'!$CB13+' Follow Up 1st'!$CC13)/2 -> 2.5 | CL13: =(' Follow Up 1st'!$CD13+' Follow Up 1st'!$CE13)/2 -> 22921.5 | CM13: 5
A14: 12 | B14: Khalid Mohammed Yousef Almulhim | C14: 4A | D14: 5 | E14: 5 | F14: 5 | G14: 5 | H14: 5 | I14: 5 | J14: 5 | K14: 5 | L14: 5 | M14: 5 | N14: 5 | O14: 5 | P14: 5 | Q14: 5 | R14: 5 | S14: 5 | T14: 5 | U14: 5 | V14: 5 | W14: 5 | X14: 5 | Y14: 5 | Z14: 5 | AA14: 5 | AB14: 5 | AC14: 5 | AD14: 5 | AE14: 5 | AF14: 5 | AG14: 5 | AH14: 5 | AI14: 5 | AJ14: 5 | AK14: 5 | AL14: 5 | AM14: 5 | AN14: 5 | AO14: 5 | AP14: 5 | AQ14: 5 | AR14: 5 | AS14: 5 | AT14: 5 | AU14: 5 | CB14: 5 | CD14: 45905 | CF14: 5 | CG14: =AVERAGE(BX14,BT14,BP14,BL14,BH14,BD14,AZ14,AV14,AR14,AN14,AJ14,AF14,AB14,X14,T14,P14,L14,H14,D14) -> 5 | CH14: =AVERAGE(BY14,BU14,BQ14,BM14,BI14,BE14,BA14,AW14,AS14,AO14,AK14,AG14,AC14,Y14,U14,Q14,M14,I14,E14) -> 5 | CI14: =AVERAGE(BZ14,BV14,BR14,BN14,BJ14,BF14,BB14,AX14,AT14,AP14,AL14,AH14,AD14,Z14,V14,R14,N14,J14,F14) -> 5 | CJ14: =AVERAGE(CA14,BW14,BS14,BO14,BK14,BG14,BC14,AY14,AU14,AQ14,AM14,AI14,AE14,AA14,W14,S14,O14,K14,G14) -> 5 | CK14: =(' Follow Up 1st'!$CB14+' Follow Up 1st'!$CC14)/2 -> 2.5 | CL14: =(' Follow Up 1st'!$CD14+' Follow Up 1st'!$CE14)/2 -> 22952.5 | CM14: 5
... A61: 59 | B61: AHMED ABDULMONEM ALMAGED | C61: 5A | D61: 5 | E61: 5 | F61: 5 | G61: 5 | H61: 5 | I61: 5 | J61: 5 | K61: 5 | L61: 5 | M61: 5 | N61: 5 | O61: 0 | P61: 5 | Q61: 5 | R61: 5 | S61: 5 | T61: 5 | U61: 5 | V61: 5 | W61: 5 | X61: 5 | Y61: 5 | Z61: 5 | AA61: 5 | AB61: 5 | AC61: 5 | AD61: 5 | AE61: 5 | AF61: 5 | AG61: 5 | AH61: 5 | AI61: 5 | AJ61: 5 | AK61: 5 | AL61: 5 | AM61: 5 | AN61: 5 | AO61: 5 | AP61: 5 | AQ61: 5 | AR61: 5 | AS61: 5 | AT61: 5 | AU61: 5 | CB61: 3 | CD61: 7 | CF61: 5 | CG61: =AVERAGE(BX61,BT61,BP61,BL61,BH61,BD61,AZ61,AV61,AR61,AN61,AJ61,AF61,AB61,X61,T61,P61,L61,H61,D61) -> 5 | CH61: =AVERAGE(BY61,BU61,BQ61,BM61,BI61,BE61,BA61,AW61,AS61,AO61,AK61,AG61,AC61,Y61,U61,Q61,M61,I61,E61) -> 5 | CI61: =AVERAGE(BZ61,BV61,BR61,BN61,BJ61,BF61,BB61,AX61,AT61,AP61,AL61,AH61,AD61,Z61,V61,R61,N61,J61,F61) -> 5 | CJ61: =AVERAGE(CA61,BW61,BS61,BO61,BK61,BG61,BC61,AY61,AU61,AQ61,AM61,AI61,AE61,AA61,W61,S61,O61,K61,G61) -> 4.5454545 | CK61: =(' Follow Up 1st'!$CB61+' Follow Up 1st'!$CC61)/2 -> 1.5 | CL61: =(' Follow Up 1st'!$CD61+' Follow Up 1st'!$CE61)/2 -> 3.5 | CM61: 5
A62: 60 | B62: AHMAD NAJI AHMAD FLITI | C62: 5B | D62: 5 | E62: 5 | F62: 5 | G62: 5 | H62: 5 | I62: 5 | J62: 5 | K62: 5 | L62: 5 | M62: 5 | N62: 5 | O62: 5 | P62: 5 | Q62: 5 | R62: 5 | S62: 5 | T62: 5 | U62: 5 | V62: 5 | W62: 5 | X62: 5 | Y62: 5 | Z62: 5 | AA62: 5 | AB62: 5 | AC62: 5 | AD62: 5 | AE62: 5 | AF62: 5 | AG62: 5 | AH62: 5 | AI62: 5 | AJ62: 5 | AK62: 5 | AL62: 5 | AM62: 5 | AN62: 5 | AO62: 5 | AP62: 5 | AQ62: 5 | CB62: 5 | CD62: 45874 | CF62: 5 | CG62: =AVERAGE(BX62,BT62,BP62,BL62,BH62,BD62,AZ62,AV62,AR62,AN62,AJ62,AF62,AB62,X62,T62,P62,L62,H62,D62) -> 5 | CH62: =AVERAGE(BY62,BU62,BQ62,BM62,BI62,BE62,BA62,AW62,AS62,AO62,AK62,AG62,AC62,Y62,U62,Q62,M62,I62,E62) -> 5 | CI62: =AVERAGE(BZ62,BV62,BR62,BN62,BJ62,BF62,BB62,AX62,AT62,AP62,AL62,AH62,AD62,Z62,V62,R62,N62,J62,F62) -> 5 | CJ62: =AVERAGE(CA62,BW62,BS62,BO62,BK62,BG62,BC62,AY62,AU62,AQ62,AM62,AI62,AE62,AA62,W62,S62,O62,K62,G62) -> 5 | CK62: =(' Follow Up 1st'!$CB62+' Follow Up 1st'!$CC62)/2 -> 2.5 | CL62: =(' Follow Up 1st'!$CD62+' Follow Up 1st'!$CE62)/2 -> 22937 | CM62: 5
A63: 61 | B63: HASSAN MAITHAM TAHER AL HABARH | C63: 5B | D63: 5 | E63: 5 | F63: 5 | G63: 5 | H63: 5 | I63: 5 | J63: 5 | K63: 5 | L63: 5 | M63: 5 | N63: 5 | O63: 5 | P63: 5 | Q63: 5 | R63: 5 | S63: 5 | T63: 5 | U63: 5 | V63: 5 | W63: 5 | X63: 5 | Y63: 5 | Z63: 5 | AA63: 5 | AB63: 5 | AC63: 5 | AD63: 5 | AE63: 5 | AF63: 5 | AG63: 5 | AH63: 5 | AI63: 5 | AJ63: 5 | AK63: 5 | AL63: 5 | AM63: 5 | AN63: 5 | AO63: 5 | AP63: 5 | AQ63: 5 | CB63: 5 | CD63: 45905 | CF63: 5 | CG63: =AVERAGE(BX63,BT63,BP63,BL63,BH63,BD63,AZ63,AV63,AR63,AN63,AJ63,AF63,AB63,X63,T63,P63,L63,H63,D63) -> 5 | CH63: =AVERAGE(BY63,BU63,BQ63,BM63,BI63,BE63,BA63,AW63,AS63,AO63,AK63,AG63,AC63,Y63,U63,Q63,M63,I63,E63) -> 5 | CI63: =AVERAGE(BZ63,BV63,BR63,BN63,BJ63,BF63,BB63,AX63,AT63,AP63,AL63,AH63,AD63,Z63,V63,R63,N63,J63,F63) -> 5 | CJ63: =AVERAGE(CA63,BW63,BS63,BO63,BK63,BG63,BC63,AY63,AU63,AQ63,AM63,AI63,AE63,AA63,W63,S63,O63,K63,G63) -> 5 | CK63: =(' Follow Up 1st'!$CB63+' Follow Up 1st'!$CC63)/2 -> 2.5 | CL63: =(' Follow Up 1st'!$CD63+' Follow Up 1st'!$CE63)/2 -> 22952.5 | CM63: 5
A64: 62 | B64: TALIB WASIL MOHAMMED ALNAHWE | C64: 5B | D64: 5 | E64: 5 | F64: 5 | G64: 5 | H64: 5 | I64: 5 | J64: 5 | K64: 5 | L64: 5 | M64: 5 | N64: 5 | O64: 5 | P64: 5 | Q64: 5 | R64: 5 | S64: 5 | T64: 5 | U64: 5 | V64: 5 | W64: 5 | X64: 5 | Y64: 5 | Z64: 5 | AA64: 5 | AB64: 5 | AC64: 5 | AD64: 5 | AE64: 5 | AF64: 5 | AG64: 5 | AH64: 5 | AI64: 5 | AJ64: 5 | AK64: 5 | AL64: 5 | AM64: 5 | AN64: 5 | AO64: 5 | AP64: 5 | AQ64: 5 | CB64: 5 | CD64: 45905 | CF64: 5 | CG64: =AVERAGE(BX64,BT64,BP64,BL64,BH64,BD64,AZ64,AV64,AR64,AN64,AJ64,AF64,AB64,X64,T64,P64,L64,H64,D64) -> 5 | CH64: =AVERAGE(BY64,BU64,BQ64,BM64,BI64,BE64,BA64,AW64,AS64,AO64,AK64,AG64,AC64,Y64,U64,Q64,M64,I64,E64) -> 5 | CI64: =AVERAGE(BZ64,BV64,BR64,BN64,BJ64,BF64,BB64,AX64,AT64,AP64,AL64,AH64,AD64,Z64,V64,R64,N64,J64,F64) -> 5 | CJ64: =AVERAGE(CA64,BW64,BS64,BO64,BK64,BG64,BC64,AY64,AU64,AQ64,AM64,AI64,AE64,AA64,W64,S64,O64,K64,G64) -> 5 | CK64: =(' Follow Up 1st'!$CB64+' Follow Up 1st'!$CC64)/2 -> 2.5 | CL64: =(' Follow Up 1st'!$CD64+' Follow Up 1st'!$CE64)/2 -> 22952.5 | CM64: 5
A65: 63 | B65: JALAWI BIN FAISAL BIN FAHAD ALSAUD | C65: 5B | D65: 5 | E65: 5 | F65: 5 | G65: 5 | H65: 5 | I65: 5 | J65: 5 | K65: 5 | L65: 5 | M65: 5 | N65: 3 | O65: 5 | P65: 5 | Q65: 5 | R65: 5 | S65: 5 | T65: 5 | U65: 5 | V65: 5 | W65: 5 | X65: 5 | Y65: 5 | Z65: 5 | AA65: 5 | AB65: 5 | AC65: 5 | AD65: 5 | AE65: 5 | AF65: 5 | AG65: 5 | AH65: 5 | AI65: 5 | AJ65: 5 | AK65: 5 | AL65: 5 | AM65: 5 | AN65: 5 | AO65: 5 | AP65: 5 | AQ65: 5 | CB65: 5 | CD65: 9 | CF65: 5 | CG65: =AVERAGE(BX65,BT65,BP65,BL65,BH65,BD65,AZ65,AV65,AR65,AN65,AJ65,AF65,AB65,X65,T65,P65,L65,H65,D65) -> 5 | CH65: =AVERAGE(BY65,BU65,BQ65,BM65,BI65,BE65,BA65,AW65,AS65,AO65,AK65,AG65,AC65,Y65,U65,Q65,M65,I65,E65) -> 5 | CI65: =AVERAGE(BZ65,BV65,BR65,BN65,BJ65,BF65,BB65,AX65,AT65,AP65,AL65,AH65,AD65,Z65,V65,R65,N65,J65,F65) -> 4.8 | CJ65: =AVERAGE(CA65,BW65,BS65,BO65,BK65,BG65,BC65,AY65,AU65,AQ65,AM65,AI65,AE65,AA65,W65,S65,O65,K65,G65) -> 5 | CK65: =(' Follow Up 1st'!$CB65+' Follow Up 1st'!$CC65)/2 -> 2.5 | CL65: =(' Follow Up 1st'!$CD65+' Follow Up 1st'!$CE65)/2 -> 4.5 | CM65: 5
A66: 64 | B66: ABDULAZIZ FAHAD AHMED ALMOUTLAQ | C66: 5B | D66: 5 | E66: 5 | F66: 5 | G66: 5 | H66: 5 | I66: 5 | J66: 5 | K66: 5 | L66: 5 | M66: 5 | N66: 5 | O66: 5 | P66: 5 | Q66: 5 | R66: 5 | S66: 5 | T66: 5 | U66: 5 | V66: 5 | W66: 5 | X66: 5 | Y66: 5 | Z66: 5 | AA66: 5 | AB66: 5 | AC66: 5 | AD66: 5 | AE66: 5 | AF66: 5 | AG66: 5 | AH66: 5 | AI66: 5 | AJ66: 5 | AK66: 5 | AL66: 5 | AM66: 5 | AN66: 5 | AO66: 5 | AP66: 5 | AQ66: 5 | CB66: 4 | CD66: 45874 | CF66: 5 | CG66: =AVERAGE(BX66,BT66,BP66,BL66,BH66,BD66,AZ66,AV66,AR66,AN66,AJ66,AF66,AB66,X66,T66,P66,L66,H66,D66) -> 5 | CH66: =AVERAGE(BY66,BU66,BQ66,BM66,BI66,BE66,BA66,AW66,AS66,AO66,AK66,AG66,AC66,Y66,U66,Q66,M66,I66,E66) -> 5 | CI66: =AVERAGE(BZ66,BV66,BR66,BN66,BJ66,BF66,BB66,AX66,AT66,AP66,AL66,AH66,AD66,Z66,V66,R66,N66,J66,F66) -> 5 | CJ66: =AVERAGE(CA66,BW66,BS66,BO66,BK66,BG66,BC66,AY66,AU66,AQ66,AM66,AI66,AE66,AA66,W66,S66,O66,K66,G66) -> 5 | CK66: =(' Follow Up 1st'!$CB66+' Follow Up 1st'!$CC66)/2 -> 2 | CL66: =(' Follow Up 1st'!$CD66+' Follow Up 1st'!$CE66)/2 -> 22937 | CM66: 5
A67: 65 | B67: ABDULLAH ABDULRAHMAN ABDULLAH BOODAI | C67: 5B | D67: 5 | E67: 5 | F67: 5 | G67: 5 | H67: 5 | I67: 5 | J67: 5 | K67: 5 | L67: 5 | M67: 3 | N67: 3 | O67: 0 | P67: 3 | Q67: 5 | R67: 5 | S67: 5 | T67: 5 | U67: 5 | V67: 5 | W67: 5 | X67: 5 | Y67: 5 | Z67: 5 | AA67: 5 | AB67: 5 | AC67: 5 | AD67: 5 | AE67: 5 | AF67: 5 | AG67: 5 | AH67: 5 | AI67: 5 | AJ67: 5 | AK67: 5 | AL67: 5 | AM67: 5 | AN67: 5 | AO67: 5 | AP67: 5 | AQ67: 5 | CB67: 3 | CD67: 8 | CF67: 5 | CG67: =AVERAGE(BX67,BT67,BP67,BL67,BH67,BD67,AZ67,AV67,AR67,AN67,AJ67,AF67,AB67,X67,T67,P67,L67,H67,D67) -> 4.8 | CH67: =AVERAGE(BY67,BU67,BQ67,BM67,BI67,BE67,BA67,AW67,AS67,AO67,AK67,AG67,AC67,Y67,U67,Q67,M67,I67,E67) -> 4.8 | CI67: =AVERAGE(BZ67,BV67,BR67,BN67,BJ67,BF67,BB67,AX67,AT67,AP67,AL67,AH67,AD67,Z67,V67,R67,N67,J67,F67) -> 4.8 | CJ67: =AVERAGE(CA67,BW67,BS67,BO67,BK67,BG67,BC67,AY67,AU67,AQ67,AM67,AI67,AE67,AA67,W67,S67,O67,K67,G67) -> 4.5 | CK67: =(' Follow Up 1st'!$CB67+' Follow Up 1st'!$CC67)/2 -> 1.5 | CL67: =(' Follow Up 1st'!$CD67+' Follow Up 1st'!$CE67)/2 -> 4 | CM67: 5
A68: 66 | B68: OMAR MAJED ABDULLATIF IBN DEHAISH | C68: 5B | D68: 5 | E68: 5 | F68: 5 | G68: 5 | H68: 5 | I68: 5 | J68: 5 | K68: 5 | L68: 5 | M68: 3 | N68: 3 | O68: 5 | P68: 5 | Q68: 5 | R68: 5 | S68: 5 | T68: 5 | U68: 5 | V68: 5 | W68: 5 | X68: 5 | Y68: 5 | Z68: 5 | AA68: 5 | AB68: 5 | AC68: 5 | AD68: 5 | AE68: 5 | AF68: 5 | AG68: 5 | AH68: 5 | AI68: 5 | AJ68: 5 | AK68: 5 | AL68: 5 | AM68: 5 | AN68: 5 | AO68: 5 | AP68: 5 | AQ68: 5 | CB68: 5 | CD68: 45905 | CF68: 5 | CG68: =AVERAGE(BX68,BT68,BP68,BL68,BH68,BD68,AZ68,AV68,AR68,AN68,AJ68,AF68,AB68,X68,T68,P68,L68,H68,D68) -> 5 | CH68: =AVERAGE(BY68,BU68,BQ68,BM68,BI68,BE68,BA68,AW68,AS68,AO68,AK68,AG68,AC68,Y68,U68,Q68,M68,I68,E68) -> 4.8 | CI68: =AVERAGE(BZ68,BV68,BR68,BN68,BJ68,BF68,BB68,AX68,AT68,AP68,AL68,AH68,AD68,Z68,V68,R68,N68,J68,F68) -> 4.8 | CJ68: =AVERAGE(CA68,BW68,BS68,BO68,BK68,BG68,BC68,AY68,AU68,AQ68,AM68,AI68,AE68,AA68,W68,S68,O68,K68,G68) -> 5 | CK68: =(' Follow Up 1st'!$CB68+' Follow Up 1st'!$CC68)/2 -> 2.5 | CL68: =(' Follow Up 1st'!$CD68+' Follow Up 1st'!$CE68)/2 -> 22952.5 | CM68: 5
A69: 67 | B69: MOHAMMAD HASSAN ABDULLAH ALKHUDAIRY | C69: 5B | D69: 5 | E69: 5 | F69: 5 | G69: 5 | H69: 5 | I69: 5 | J69: 5 | K69: 5 | L69: 5 | M69: 3 | N69: 3 | O69: 5 | P69: 5 | Q69: 5 | R69: 5 | S69: 5 | T69: 5 | U69: 5 | V69: 5 | W69: 5 | X69: 5 | Y69: 5 | Z69: 5 | AA69: 5 | AB69: 5 | AC69: 5 | AD69: 5 | AE69: 5 | AF69: 5 | AG69: 5 | AH69: 5 | AI69: 5 | AJ69: 5 | AK69: 5 | AL69: 5 | AM69: 5 | AN69: 5 | AO69: 5 | AP69: 5 | AQ69: 5 | CB69: 5 | CD69: 8 | CF69: 5 | CG69: =AVERAGE(BX69,BT69,BP69,BL69,BH69,BD69,AZ69,AV69,AR69,AN69,AJ69,AF69,AB69,X69,T69,P69,L69,H69,D69) -> 5 | CH69: =AVERAGE(BY69,BU69,BQ69,BM69,BI69,BE69,BA69,AW69,AS69,AO69,AK69,AG69,AC69,Y69,U69,Q69,M69,I69,E69) -> 4.8 | CI69: =AVERAGE(BZ69,BV69,BR69,BN69,BJ69,BF69,BB69,AX69,AT69,AP69,AL69,AH69,AD69,Z69,V69,R69,N69,J69,F69) -> 4.8 | CJ69: =AVERAGE(CA69,BW69,BS69,BO69,BK69,BG69,BC69,AY69,AU69,AQ69,AM69,AI69,AE69,AA69,W69,S69,O69,K69,G69) -> 5 | CK69: =(' Follow Up 1st'!$CB69+' Follow Up 1st'!$CC69)/2 -> 2.5 | CL69: =(' Follow Up 1st'!$CD69+' Follow Up 1st'!$CE69)/2 -> 4 | CM69: 5
A70: 68 | B70: MOHAMMED ESSA MOHAMMED ALBISHER | C70: 5B | D70: 5 | E70: 5 | F70: 5 | G70: 5 | H70: 5 | I70: 5 | J70: 5 | K70: 5 | L70: 5 | M70: 5 | N70: 5 | O70: 5 | P70: 5 | Q70: 5 | R70: 5 | S70: 5 | T70: 5 | U70: 5 | V70: 5 | W70: 5 | X70: 5 | Y70: 5 | Z70: 5 | AA70: 5 | AB70: 5 | AC70: 5 | AD70: 5 | AE70: 5 | AF70: 5 | AG70: 5 | AH70: 5 | AI70: 5 | AJ70: 5 | AK70: 5 | AL70: 5 | AM70: 5 | AN70: 5 | AO70: 5 | AP70: 5 | AQ70: 5 | CB70: 5 | CD70: 45905 | CF70: 5 | CG70: =AVERAGE(BX70,BT70,BP70,BL70,BH70,BD70,AZ70,AV70,AR70,AN70,AJ70,AF70,AB70,X70,T70,P70,L70,H70,D70) -> 5 | CH70: =AVERAGE(BY70,BU70,BQ70,BM70,BI70,BE70,BA70,AW70,AS70,AO70,AK70,AG70,AC70,Y70,U70,Q70,M70,I70,E70) -> 5 | CI70: =AVERAGE(BZ70,BV70,BR70,BN70,BJ70,BF70,BB70,AX70,AT70,AP70,AL70,AH70,AD70,Z70,V70,R70,N70,J70,F70) -> 5 | CJ70: =AVERAGE(CA70,BW70,BS70,BO70,BK70,BG70,BC70,AY70,AU70,AQ70,AM70,AI70,AE70,AA70,W70,S70,O70,K70,G70) -> 5 | CK70: =(' Follow Up 1st'!$CB70+' Follow Up 1st'!$CC70)/2 -> 2.5 | CL70: =(' Follow Up 1st'!$CD70+' Follow Up 1st'!$CE70)/2 -> 22952.5 | CM70: 5
A71: 69 | B71: MOHAMMED NAYIF AWADH AL OTAIBI | C71: 5B | D71: 5 | E71: 5 | F71: 5 | G71: 5 | H71: 5 | I71: 5 | J71: 5 | K71: 5 | L71: 5 | M71: 5 | N71: 5 | O71: 5 | P71: 5 | Q71: 5 | R71: 5 | S71: 5 | T71: 5 | U71: 5 | V71: 5 | W71: 5 | X71: 5 | Y71: 5 | Z71: 5 | AA71: 5 | AB71: 5 | AC71: 5 | AD71: 5 | AE71: 5 | AF71: 5 | AG71: 5 | AH71: 5 | AI71: 5 | AJ71: 5 | AK71: 5 | AL71: 5 | AM71: 5 | AN71: 5 | AO71: 5 | AP71: 5 | AQ71: 5 | CB71: 4 | CD71: 45874 | CF71: 5 | CG71: =AVERAGE(BX71,BT71,BP71,BL71,BH71,BD71,AZ71,AV71,AR71,AN71,AJ71,AF71,AB71,X71,T71,P71,L71,H71,D71) -> 5 | CH71: =AVERAGE(BY71,BU71,BQ71,BM71,BI71,BE71,BA71,AW71,AS71,AO71,AK71,AG71,AC71,Y71,U71,Q71,M71,I71,E71) -> 5 | CI71: =AVERAGE(BZ71,BV71,BR71,BN71,BJ71,BF71,BB71,AX71,AT71,AP71,AL71,AH71,AD71,Z71,V71,R71,N71,J71,F71) -> 5 | CJ71: =AVERAGE(CA71,BW71,BS71,BO71,BK71,BG71,BC71,AY71,AU71,AQ71,AM71,AI71,AE71,AA71,W71,S71,O71,K71,G71) -> 5 | CK71: =(' Follow Up 1st'!$CB71+' Follow Up 1st'!$CC71)/2 -> 2 | CL71: =(' Follow Up 1st'!$CD71+' Follow Up 1st'!$CE71)/2 -> 22937 | CM71: 5
A72: 70 | B72: IBRAHIM ZIYAD ALDOSSARY | C72: 5B | D72: 5 | E72: 5 | F72: 5 | G72: 5 | H72: 5 | I72: 5 | J72: 5 | K72: 5 | L72: 5 | M72: 5 | N72: 5 | O72: 5 | P72: 5 | Q72: 5 | R72: 5 | S72: 5 | T72: 5 | U72: 5 | V72: 5 | W72: 5 | X72: 5 | Y72: 5 | Z72: 5 | AA72: 5 | AB72: 5 | AC72: 5 | AD72: 5 | AE72: 5 | AF72: 5 | AG72: 5 | AH72: 5 | AI72: 5 | AJ72: 5 | AK72: 5 | AL72: 5 | AM72: 5 | AN72: 5 | AO72: 5 | AP72: 5 | AQ72: 5 | CB72: 5 | CD72: 45874 | CF72: 5 | CG72: =AVERAGE(BX72,BT72,BP72,BL72,BH72,BD72,AZ72,AV72,AR72,AN72,AJ72,AF72,AB72,X72,T72,P72,L72,H72,D72) -> 5 | CH72: =AVERAGE(BY72,BU72,BQ72,BM72,BI72,BE72,BA72,AW72,AS72,AO72,AK72,AG72,AC72,Y72,U72,Q72,M72,I72,E72) -> 5 | CI72: =AVERAGE(BZ72,BV72,BR72,BN72,BJ72,BF72,BB72,AX72,AT72,AP72,AL72,AH72,AD72,Z72,V72,R72,N72,J72,F72) -> 5 | CJ72: =AVERAGE(CA72,BW72,BS72,BO72,BK72,BG72,BC72,AY72,AU72,AQ72,AM72,AI72,AE72,AA72,W72,S72,O72,K72,G72) -> 5 | CK72: =(' Follow Up 1st'!$CB72+' Follow Up 1st'!$CC72)/2 -> 2.5 | CL72: =(' Follow Up 1st'!$CD72+' Follow Up 1st'!$CE72)/2 -> 22937 | CM72: 5
A73: 71 | B73: IBRAHIM YOUSEF IBRAHIM ALBORSAIS | C73: 6A | D73: 5 | E73: 5 | F73: 5 | G73: 5 | H73: 5 | I73: 5 | J73: 5 | K73: 5 | L73: 5 | M73: 3 | N73: 5 | O73: 5 | P73: 5 | Q73: 5 | R73: 5 | S73: 5 | T73: 5 | U73: 5 | V73: 5 | W73: 0 | X73: 5 | Y73: 5 | Z73: 5 | AA73: 5 | AB73: 5 | AC73: 5 | AD73: 5 | AE73: 5 | AF73: 5 | AG73: 5 | AH73: 5 | AI73: 5 | AJ73: 5 | AK73: 5 | AL73: 5 | AM73: 5 | AN73: 5 | AO73: 5 | AP73: 5 | AQ73: 5 | CB73: 4 | CD73: 7 | CF73: 5 | CG73: =AVERAGE(BX73,BT73,BP73,BL73,BH73,BD73,AZ73,AV73,AR73,AN73,AJ73,AF73,AB73,X73,T73,P73,L73,H73,D73) -> 5 | CH73: =AVERAGE(BY73,BU73,BQ73,BM73,BI73,BE73,BA73,AW73,AS73,AO73,AK73,AG73,AC73,Y73,U73,Q73,M73,I73,E73) -> 4.8 | CI73: =AVERAGE(BZ73,BV73,BR73,BN73,BJ73,BF73,BB73,AX73,AT73,AP73,AL73,AH73,AD73,Z73,V73,R73,N73,J73,F73) -> 5 | CJ73: =AVERAGE(CA73,BW73,BS73,BO73,BK73,BG73,BC73,AY73,AU73,AQ73,AM73,AI73,AE73,AA73,W73,S73,O73,K73,G73) -> 4.5 | CK73: =(' Follow Up 1st'!$CB73+' Follow Up 1st'!$CC73)/2 -> 2 | CL73: =(' Follow Up 1st'!$CD73+' Follow Up 1st'!$CE73)/2 -> 3.5 | CM73: 5
... A90: 88 | B90: MOHAMMED ABDULMAJID MOHAMMED AL ARFAJ | C90: 6A | D90: 5 | E90: 5 | F90: 5 | G90: 5 | H90: 5 | I90: 5 | J90: 5 | K90: 5 | L90: 5 | M90: 5 | N90: 5 | O90: 5 | P90: 5 | Q90: 5 | R90: 5 | S90: 5 | T90: 5 | U90: 5 | V90: 5 | W90: 5 | X90: 5 | Y90: 5 | Z90: 5 | AA90: 5 | AB90: 5 | AC90: 5 | AD90: 5 | AE90: 5 | AF90: 5 | AG90: 5 | AH90: 5 | AI90: 5 | AJ90: 5 | AK90: 5 | AL90: 5 | AM90: 5 | AN90: 5 | AO90: 5 | AP90: 5 | AQ90: 5 | CB90: 5 | CD90: 10 | CF90: 5 | CG90: =AVERAGE(BX90,BT90,BP90,BL90,BH90,BD90,AZ90,AV90,AR90,AN90,AJ90,AF90,AB90,X90,T90,P90,L90,H90,D90) -> 5 | CH90: =AVERAGE(BY90,BU90,BQ90,BM90,BI90,BE90,BA90,AW90,AS90,AO90,AK90,AG90,AC90,Y90,U90,Q90,M90,I90,E90) -> 5 | CI90: =AVERAGE(BZ90,BV90,BR90,BN90,BJ90,BF90,BB90,AX90,AT90,AP90,AL90,AH90,AD90,Z90,V90,R90,N90,J90,F90) -> 5 | CJ90: =AVERAGE(CA90,BW90,BS90,BO90,BK90,BG90,BC90,AY90,AU90,AQ90,AM90,AI90,AE90,AA90,W90,S90,O90,K90,G90) -> 5 | CK90: =(' Follow Up 1st'!$CB90+' Follow Up 1st'!$CC90)/2 -> 2.5 | CL90: =(' Follow Up 1st'!$CD90+' Follow Up 1st'!$CE90)/2 -> 5 | CM90: 5
A91: 89 | B91: YOUSEF MOHAMMED YOUSEF ALMULHIM | C91: 6B | D91: 5 | E91: 5 | F91: 5 | G91: 5 | H91: 5 | I91: 5 | J91: 5 | K91: 5 | L91: 5 | M91: 5 | N91: 5 | O91: 5 | P91: 5 | Q91: 5 | R91: 5 | S91: 5 | T91: 5 | U91: 5 | V91: 5 | W91: 5 | X91: 5 | Y91: 5 | Z91: 5 | AA91: 5 | AB91: 5 | AC91: 5 | AD91: 5 | AE91: 5 | AF91: 5 | AG91: 5 | AH91: 5 | AI91: 5 | AJ91: 5 | AK91: 5 | AL91: 5 | AM91: 5 | AN91: 5 | AO91: 5 | AP91: 5 | AQ91: 5 | AR91: 5 | AS91: 5 | AT91: 5 | AU91: 5 | CB91: 5 | CD91: 10 | CF91: 5 | CG91: =AVERAGE(BX91,BT91,BP91,BL91,BH91,BD91,AZ91,AV91,AR91,AN91,AJ91,AF91,AB91,X91,T91,P91,L91,H91,D91) -> 5 | CH91: =AVERAGE(BY91,BU91,BQ91,BM91,BI91,BE91,BA91,AW91,AS91,AO91,AK91,AG91,AC91,Y91,U91,Q91,M91,I91,E91) -> 5 | CI91: =AVERAGE(BZ91,BV91,BR91,BN91,BJ91,BF91,BB91,AX91,AT91,AP91,AL91,AH91,AD91,Z91,V91,R91,N91,J91,F91) -> 5 | CJ91: =AVERAGE(CA91,BW91,BS91,BO91,BK91,BG91,BC91,AY91,AU91,AQ91,AM91,AI91,AE91,AA91,W91,S91,O91,K91,G91) -> 5 | CK91: =(' Follow Up 1st'!$CB91+' Follow Up 1st'!$CC91)/2 -> 2.5 | CL91: =(' Follow Up 1st'!$CD91+' Follow Up 1st'!$CE91)/2 -> 5 | CM91: 5
A92: 90 | B92: SALEH HUSSAIN SALEH ALHEJJI | C92: 6B | D92: 5 | E92: 5 | F92: 5 | G92: 5 | H92: 5 | I92: 5 | J92: 5 | K92: 5 | L92: 5 | M92: 5 | N92: 5 | O92: 5 | P92: 5 | Q92: 5 | R92: 5 | S92: 5 | T92: 5 | U92: 5 | V92: 5 | W92: 5 | X92: 5 | Y92: 5 | Z92: 5 | AA92: 5 | AB92: 5 | AC92: 5 | AD92: 5 | AE92: 5 | AF92: 5 | AG92: 5 | AH92: 5 | AI92: 5 | AJ92: 5 | AK92: 5 | AL92: 5 | AM92: 5 | AN92: 5 | AO92: 5 | AP92: 5 | AQ92: 5 | AR92: 5 | AS92: 5 | AT92: 5 | AU92: 5 | CB92: 4 | CD92: 8 | CF92: 5 | CG92: =AVERAGE(BX92,BT92,BP92,BL92,BH92,BD92,AZ92,AV92,AR92,AN92,AJ92,AF92,AB92,X92,T92,P92,L92,H92,D92) -> 5 | CH92: =AVERAGE(BY92,BU92,BQ92,BM92,BI92,BE92,BA92,AW92,AS92,AO92,AK92,AG92,AC92,Y92,U92,Q92,M92,I92,E92) -> 5 | CI92: =AVERAGE(BZ92,BV92,BR92,BN92,BJ92,BF92,BB92,AX92,AT92,AP92,AL92,AH92,AD92,Z92,V92,R92,N92,J92,F92) -> 5 | CJ92: =AVERAGE(CA92,BW92,BS92,BO92,BK92,BG92,BC92,AY92,AU92,AQ92,AM92,AI92,AE92,AA92,W92,S92,O92,K92,G92) -> 5 | CK92: =(' Follow Up 1st'!$CB92+' Follow Up 1st'!$CC92)/2 -> 2 | CL92: =(' Follow Up 1st'!$CD92+' Follow Up 1st'!$CE92)/2 -> 4 | CM92: 5
A93: 91 | B93: ABDULLAH THAMIR SAAD AL BARRAK | C93: 6B | D93: 5 | E93: 5 | F93: 5 | G93: 5 | H93: 5 | I93: 5 | J93: 5 | K93: 5 | L93: 5 | M93: 5 | N93: 5 | O93: 5 | P93: 5 | Q93: 5 | R93: 5 | S93: 5 | T93: 5 | U93: 5 | V93: 5 | W93: 5 | X93: 5 | Y93: 5 | Z93: 5 | AA93: 5 | AB93: 5 | AC93: 5 | AD93: 5 | AE93: 5 | AF93: 5 | AG93: 5 | AH93: 5 | AI93: 5 | AJ93: 5 | AK93: 5 | AL93: 5 | AM93: 5 | AN93: 5 | AO93: 2 | AP93: 5 | AQ93: 5 | AR93: 5 | AS93: 5 | AT93: 5 | AU93: 5 | CB93: 5 | CD93: 10 | CF93: 5 | CG93: =AVERAGE(BX93,BT93,BP93,BL93,BH93,BD93,AZ93,AV93,AR93,AN93,AJ93,AF93,AB93,X93,T93,P93,L93,H93,D93) -> 5 | CH93: =AVERAGE(BY93,BU93,BQ93,BM93,BI93,BE93,BA93,AW93,AS93,AO93,AK93,AG93,AC93,Y93,U93,Q93,M93,I93,E93) -> 4.7272727 | CI93: =AVERAGE(BZ93,BV93,BR93,BN93,BJ93,BF93,BB93,AX93,AT93,AP93,AL93,AH93,AD93,Z93,V93,R93,N93,J93,F93) -> 5 | CJ93: =AVERAGE(CA93,BW93,BS93,BO93,BK93,BG93,BC93,AY93,AU93,AQ93,AM93,AI93,AE93,AA93,W93,S93,O93,K93,G93) -> 5 | CK93: =(' Follow Up 1st'!$CB93+' Follow Up 1st'!$CC93)/2 -> 2.5 | CL93: =(' Follow Up 1st'!$CD93+' Follow Up 1st'!$CE93)/2 -> 5 | CM93: 5
A94: 92 | B94: ABDULLAH NASSER ABDULLAH ALSAQER | C94: 6B | D94: 5 | E94: 5 | F94: 5 | G94: 5 | H94: 5 | I94: 5 | J94: 5 | K94: 5 | L94: 5 | M94: 5 | N94: 5 | O94: 5 | P94: 3 | Q94: 5 | R94: 5 | S94: 5 | T94: 5 | U94: 5 | V94: 5 | W94: 5 | X94: 5 | Y94: 5 | Z94: 5 | AA94: 5 | AB94: 5 | AC94: 5 | AD94: 5 | AE94: 5 | AF94: 5 | AG94: 5 | AH94: 5 | AI94: 5 | AJ94: 5 | AK94: 5 | AL94: 5 | AM94: 5 | AN94: 5 | AO94: 5 | AP94: 5 | AQ94: 5 | AR94: 5 | AS94: 5 | AT94: 5 | AU94: 5 | CB94: 5 | CD94: 6 | CF94: 5 | CG94: =AVERAGE(BX94,BT94,BP94,BL94,BH94,BD94,AZ94,AV94,AR94,AN94,AJ94,AF94,AB94,X94,T94,P94,L94,H94,D94) -> 4.8181818 | CH94: =AVERAGE(BY94,BU94,BQ94,BM94,BI94,BE94,BA94,AW94,AS94,AO94,AK94,AG94,AC94,Y94,U94,Q94,M94,I94,E94) -> 5 | CI94: =AVERAGE(BZ94,BV94,BR94,BN94,BJ94,BF94,BB94,AX94,AT94,AP94,AL94,AH94,AD94,Z94,V94,R94,N94,J94,F94) -> 5 | CJ94: =AVERAGE(CA94,BW94,BS94,BO94,BK94,BG94,BC94,AY94,AU94,AQ94,AM94,AI94,AE94,AA94,W94,S94,O94,K94,G94) -> 5 | CK94: =(' Follow Up 1st'!$CB94+' Follow Up 1st'!$CC94)/2 -> 2.5 | CL94: =(' Follow Up 1st'!$CD94+' Follow Up 1st'!$CE94)/2 -> 3 | CM94: 5
A95: 93 | B95: ALI ABDULMOHSEN ALI AL JERY | C95: 6B | D95: 5 | E95: 5 | F95: 5 | G95: 5 | H95: 5 | I95: 5 | J95: 5 | K95: 5 | L95: 5 | M95: 5 | N95: 5 | O95: 5 | P95: 3 | Q95: 5 | R95: 5 | S95: 5 | T95: 5 | U95: 5 | V95: 5 | W95: 5 | X95: 5 | Y95: 5 | Z95: 5 | AA95: 5 | AB95: 5 | AC95: 5 | AD95: 5 | AE95: 5 | AF95: 5 | AG95: 5 | AH95: 5 | AI95: 5 | AJ95: 5 | AK95: 5 | AL95: 5 | AM95: 5 | AN95: 5 | AO95: 5 | AP95: 5 | AQ95: 5 | AR95: 5 | AS95: 5 | AT95: 5 | AU95: 5 | CB95: 4 | CD95: 8 | CF95: 5 | CG95: =AVERAGE(BX95,BT95,BP95,BL95,BH95,BD95,AZ95,AV95,AR95,AN95,AJ95,AF95,AB95,X95,T95,P95,L95,H95,D95) -> 4.8181818 | CH95: =AVERAGE(BY95,BU95,BQ95,BM95,BI95,BE95,BA95,AW95,AS95,AO95,AK95,AG95,AC95,Y95,U95,Q95,M95,I95,E95) -> 5 | CI95: =AVERAGE(BZ95,BV95,BR95,BN95,BJ95,BF95,BB95,AX95,AT95,AP95,AL95,AH95,AD95,Z95,V95,R95,N95,J95,F95) -> 5 | CJ95: =AVERAGE(CA95,BW95,BS95,BO95,BK95,BG95,BC95,AY95,AU95,AQ95,AM95,AI95,AE95,AA95,W95,S95,O95,K95,G95) -> 5 | CK95: =(' Follow Up 1st'!$CB95+' Follow Up 1st'!$CC95)/2 -> 2 | CL95: =(' Follow Up 1st'!$CD95+' Follow Up 1st'!$CE95)/2 -> 4 | CM95: 5
A96: 94 | B96: FERAS EMAD MOHAMMED ALSHEHAB | C96: 6B | D96: 5 | E96: 5 | F96: 5 | G96: 5 | H96: 5 | I96: 5 | J96: 5 | K96: 5 | L96: 5 | M96: 5 | N96: 5 | O96: 5 | P96: 5 | Q96: 5 | R96: 5 | S96: 5 | T96: 5 | U96: 5 | V96: 5 | W96: 5 | X96: 5 | Y96: 5 | Z96: 5 | AA96: 5 | AB96: 5 | AC96: 5 | AD96: 5 | AE96: 5 | AF96: 5 | AG96: 5 | AH96: 5 | AI96: 5 | AJ96: 5 | AK96: 5 | AL96: 5 | AM96: 5 | AN96: 5 | AO96: 5 | AP96: 5 | AQ96: 5 | AR96: 5 | AS96: 5 | AT96: 5 | AU96: 5 | CB96: 3 | CD96: 9 | CF96: 5 | CG96: =AVERAGE(BX96,BT96,BP96,BL96,BH96,BD96,AZ96,AV96,AR96,AN96,AJ96,AF96,AB96,X96,T96,P96,L96,H96,D96) -> 5 | CH96: =AVERAGE(BY96,BU96,BQ96,BM96,BI96,BE96,BA96,AW96,AS96,AO96,AK96,AG96,AC96,Y96,U96,Q96,M96,I96,E96) -> 5 | CI96: =AVERAGE(BZ96,BV96,BR96,BN96,BJ96,BF96,BB96,AX96,AT96,AP96,AL96,AH96,AD96,Z96,V96,R96,N96,J96,F96) -> 5 | CJ96: =AVERAGE(CA96,BW96,BS96,BO96,BK96,BG96,BC96,AY96,AU96,AQ96,AM96,AI96,AE96,AA96,W96,S96,O96,K96,G96) -> 5 | CK96: =(' Follow Up 1st'!$CB96+' Follow Up 1st'!$CC96)/2 -> 1.5 | CL96: =(' Follow Up 1st'!$CD96+' Follow Up 1st'!$CE96)/2 -> 4.5 | CM96: 5
A97: 95 | B97: HADI ALI AYESH ALALI | C97: 6B | D97: 5 | E97: 5 | F97: 5 | G97: 5 | H97: 5 | I97: 5 | J97: 5 | K97: 5 | L97: 5 | M97: 5 | N97: 5 | O97: 5 | P97: 5 | Q97: 5 | R97: 5 | S97: 5 | T97: 5 | U97: 5 | V97: 5 | W97: 5 | X97: 5 | Y97: 5 | Z97: 5 | AA97: 5 | AB97: 5 | AC97: 5 | AD97: 5 | AE97: 5 | AF97: 5 | AG97: 5 | AH97: 5 | AI97: 5 | AJ97: 5 | AK97: 5 | AL97: 5 | AM97: 5 | AN97: 5 | AO97: 5 | AP97: 5 | AQ97: 5 | AR97: 5 | AS97: 5 | AT97: 5 | AU97: 5 | CB97: 4 | CD97: 45874 | CF97: 5 | CG97: =AVERAGE(BX97,BT97,BP97,BL97,BH97,BD97,AZ97,AV97,AR97,AN97,AJ97,AF97,AB97,X97,T97,P97,L97,H97,D97) -> 5 | CH97: =AVERAGE(BY97,BU97,BQ97,BM97,BI97,BE97,BA97,AW97,AS97,AO97,AK97,AG97,AC97,Y97,U97,Q97,M97,I97,E97) -> 5 | CI97: =AVERAGE(BZ97,BV97,BR97,BN97,BJ97,BF97,BB97,AX97,AT97,AP97,AL97,AH97,AD97,Z97,V97,R97,N97,J97,F97) -> 5 | CJ97: =AVERAGE(CA97,BW97,BS97,BO97,BK97,BG97,BC97,AY97,AU97,AQ97,AM97,AI97,AE97,AA97,W97,S97,O97,K97,G97) -> 5 | CK97: =(' Follow Up 1st'!$CB97+' Follow Up 1st'!$CC97)/2 -> 2 | CL97: =(' Follow Up 1st'!$CD97+' Follow Up 1st'!$CE97)/2 -> 22937 | CM97: 5
A98: 96 | B98: AHMED ALI AHMED AL MARHOON | C98: 6B | D98: 5 | E98: 5 | F98: 5 | G98: 5 | H98: 5 | I98: 5 | J98: 5 | K98: 5 | L98: 5 | M98: 5 | N98: 5 | O98: 5 | P98: 5 | Q98: 5 | R98: 5 | S98: 5 | T98: 5 | U98: 5 | V98: 5 | W98: 5 | X98: 5 | Y98: 5 | Z98: 5 | AA98: 5 | AB98: 5 | AC98: 5 | AD98: 5 | AE98: 5 | AF98: 5 | AG98: 5 | AH98: 5 | AI98: 5 | AJ98: 5 | AK98: 5 | AL98: 5 | AM98: 5 | AN98: 5 | AO98: 5 | AP98: 5 | AQ98: 5 | AR98: 5 | AS98: 5 | AT98: 5 | AU98: 5 | CB98: 3 | CD98: 45843 | CF98: 5 | CG98: =AVERAGE(BX98,BT98,BP98,BL98,BH98,BD98,AZ98,AV98,AR98,AN98,AJ98,AF98,AB98,X98,T98,P98,L98,H98,D98) -> 5 | CH98: =AVERAGE(BY98,BU98,BQ98,BM98,BI98,BE98,BA98,AW98,AS98,AO98,AK98,AG98,AC98,Y98,U98,Q98,M98,I98,E98) -> 5 | CI98: =AVERAGE(BZ98,BV98,BR98,BN98,BJ98,BF98,BB98,AX98,AT98,AP98,AL98,AH98,AD98,Z98,V98,R98,N98,J98,F98) -> 5 | CJ98: =AVERAGE(CA98,BW98,BS98,BO98,BK98,BG98,BC98,AY98,AU98,AQ98,AM98,AI98,AE98,AA98,W98,S98,O98,K98,G98) -> 5 | CK98: =(' Follow Up 1st'!$CB98+' Follow Up 1st'!$CC98)/2 -> 1.5 | CL98: =(' Follow Up 1st'!$CD98+' Follow Up 1st'!$CE98)/2 -> 22921.5 | CM98: 5
A99: 97 | B99: ALHASAN ALI WASEL ALDANDAN | C99: 6B | D99: 5 | E99: 5 | F99: 5 | G99: 5 | H99: 5 | I99: 5 | J99: 5 | K99: 5 | L99: 5 | M99: 5 | N99: 5 | O99: 5 | P99: 5 | Q99: 5 | R99: 5 | S99: 5 | T99: 5 | U99: 5 | V99: 5 | W99: 5 | X99: 5 | Y99: 5 | Z99: 5 | AA99: 5 | AB99: 5 | AC99: 5 | AD99: 5 | AE99: 5 | AF99: 5 | AG99: 5 | AH99: 5 | AI99: 5 | AJ99: 5 | AK99: 5 | AL99: 5 | AM99: 5 | AN99: 5 | AO99: 5 | AP99: 5 | AQ99: 5 | AR99: 5 | AS99: 5 | AT99: 5 | AU99: 5 | CB99: 5 | CD99: 10 | CF99: 5 | CG99: =AVERAGE(BX99,BT99,BP99,BL99,BH99,BD99,AZ99,AV99,AR99,AN99,AJ99,AF99,AB99,X99,T99,P99,L99,H99,D99) -> 5 | CH99: =AVERAGE(BY99,BU99,BQ99,BM99,BI99,BE99,BA99,AW99,AS99,AO99,AK99,AG99,AC99,Y99,U99,Q99,M99,I99,E99) -> 5 | CI99: =AVERAGE(BZ99,BV99,BR99,BN99,BJ99,BF99,BB99,AX99,AT99,AP99,AL99,AH99,AD99,Z99,V99,R99,N99,J99,F99) -> 5 | CJ99: =AVERAGE(CA99,BW99,BS99,BO99,BK99,BG99,BC99,AY99,AU99,AQ99,AM99,AI99,AE99,AA99,W99,S99,O99,K99,G99) -> 5 | CK99: =(' Follow Up 1st'!$CB99+' Follow Up 1st'!$CC99)/2 -> 2.5 | CL99: =(' Follow Up 1st'!$CD99+' Follow Up 1st'!$CE99)/2 -> 5 | CM99: 5
A100: 98 | B100: HAMZA MOHAMED SALAHELDIN OMRAN | C100: 6B | D100: 5 | E100: 5 | F100: 5 | G100: 5 | H100: 5 | I100: 5 | J100: 5 | K100: 5 | L100: 5 | M100: 5 | N100: 5 | O100: 5 | P100: 5 | Q100: 5 | R100: 5 | S100: 5 | T100: 5 | U100: 5 | V100: 5 | W100: 5 | X100: 5 | Y100: 5 | Z100: 5 | AA100: 5 | AB100: 5 | AC100: 5 | AD100: 5 | AE100: 5 | AF100: 5 | AG100: 5 | AH100: 5 | AI100: 5 | AJ100: 5 | AK100: 5 | AL100: 5 | AM100: 5 | AN100: 5 | AO100: 5 | AP100: 5 | AQ100: 5 | AR100: 5 | AS100: 5 | AT100: 5 | AU100: 5 | CB100: 5 | CD100: 10 | CF100: 5 | CG100: =AVERAGE(BX100,BT100,BP100,BL100,BH100,BD100,AZ100,AV100,AR100,AN100,AJ100,AF100,AB100,X100,T100,P100,L100,H100,D100) -> 5 | CH100: =AVERAGE(BY100,BU100,BQ100,BM100,BI100,BE100,BA100,AW100,AS100,AO100,AK100,AG100,AC100,Y100,U100,Q100,M100,I100,E100) -> 5 | CI100: =AVERAGE(BZ100,BV100,BR100,BN100,BJ100,BF100,BB100,AX100,AT100,AP100,AL100,AH100,AD100,Z100,V100,R100,N100,J100,F100) -> 5 | CJ100: =AVERAGE(CA100,BW100,BS100,BO100,BK100,BG100,BC100,AY100,AU100,AQ100,AM100,AI100,AE100,AA100,W100,S100,O100,K100,G100) -> 5 | CK100: =(' Follow Up 1st'!$CB100+' Follow Up 1st'!$CC100)/2 -> 2.5 | CL100: =(' Follow Up 1st'!$CD100+' Follow Up 1st'!$CE100)/2 -> 5 | CM100: 5
A101: 99 | B101: KALED ABDUALRUHMAN YOSEF ALJEGHEMAN | C101: 6B | D101: 5 | E101: 5 | F101: 5 | G101: 5 | H101: 5 | I101: 5 | J101: 5 | K101: 5 | L101: 5 | M101: 5 | N101: 5 | O101: 5 | P101: 5 | Q101: 5 | R101: 5 | S101: 5 | T101: 5 | U101: 5 | V101: 5 | W101: 5 | X101: 5 | Y101: 5 | Z101: 5 | AA101: 5 | AB101: 5 | AC101: 5 | AD101: 5 | AE101: 5 | AF101: 5 | AG101: 5 | AH101: 5 | AI101: 5 | AJ101: 5 | AK101: 5 | AL101: 5 | AM101: 5 | AN101: 5 | AO101: 5 | AP101: 5 | AQ101: 5 | AR101: 5 | AS101: 5 | AT101: 5 | AU101: 5 | CB101: 3 | CD101: 8 | CF101: 5 | CG101: =AVERAGE(BX101,BT101,BP101,BL101,BH101,BD101,AZ101,AV101,AR101,AN101,AJ101,AF101,AB101,X101,T101,P101,L101,H101,D101) -> 5 | CH101: =AVERAGE(BY101,BU101,BQ101,BM101,BI101,BE101,BA101,AW101,AS101,AO101,AK101,AG101,AC101,Y101,U101,Q101,M101,I101,E101) -> 5 | CI101: =AVERAGE(BZ101,BV101,BR101,BN101,BJ101,BF101,BB101,AX101,AT101,AP101,AL101,AH101,AD101,Z101,V101,R101,N101,J101,F101) -> 5 | CJ101: =AVERAGE(CA101,BW101,BS101,BO101,BK101,BG101,BC101,AY101,AU101,AQ101,AM101,AI101,AE101,AA101,W101,S101,O101,K101,G101) -> 5 | CK101: =(' Follow Up 1st'!$CB101+' Follow Up 1st'!$CC101)/2 -> 1.5 | CL101: =(' Follow Up 1st'!$CD101+' Follow Up 1st'!$CE101)/2 -> 4 | CM101: 5
A102: 100 | B102: ABDULLAH MAHER ABDULLAH AL SAYAH | C102: 6B | D102: 5 | E102: 5 | F102: 5 | G102: 5 | H102: 5 | I102: 5 | J102: 5 | K102: 5 | L102: 5 | M102: 5 | N102: 5 | O102: 5 | P102: 5 | Q102: 5 | R102: 5 | S102: 5 | T102: 5 | U102: 5 | V102: 5 | W102: 5 | X102: 5 | Y102: 5 | Z102: 5 | AA102: 5 | AB102: 5 | AC102: 5 | AD102: 5 | AE102: 5 | AF102: 5 | AG102: 5 | AH102: 5 | AI102: 5 | AJ102: 5 | AK102: 5 | AL102: 5 | AM102: 5 | AN102: 5 | AO102: 5 | AP102: 5 | AQ102: 5 | AR102: 5 | AS102: 5 | AT102: 5 | AU102: 5 | CB102: 4 | CD102: 45813 | CF102: 5 | CG102: =AVERAGE(BX102,BT102,BP102,BL102,BH102,BD102,AZ102,AV102,AR102,AN102,AJ102,AF102,AB102,X102,T102,P102,L102,H102,D102) -> 5 | CH102: =AVERAGE(BY102,BU102,BQ102,BM102,BI102,BE102,BA102,AW102,AS102,AO102,AK102,AG102,AC102,Y102,U102,Q102,M102,I102,E102) -> 5 | CI102: =AVERAGE(BZ102,BV102,BR102,BN102,BJ102,BF102,BB102,AX102,AT102,AP102,AL102,AH102,AD102,Z102,V102,R102,N102,J102,F102) -> 5 | CJ102: =AVERAGE(CA102,BW102,BS102,BO102,BK102,BG102,BC102,AY102,AU102,AQ102,AM102,AI102,AE102,AA102,W102,S102,O102,K102,G102) -> 5 | CK102: =(' Follow Up 1st'!$CB102+' Follow Up 1st'!$CC102)/2 -> 2 | CL102: =(' Follow Up 1st'!$CD102+' Follow Up 1st'!$CE102)/2 -> 22906.5 | CM102: 5
...

Sheet Result2
A1: No | B1: Name | C1: Class | D1: First Quarter 2025 - 2026 | I1: Second Quarter 2025 - 2026 | N1: 1 St Quarter Level | O1: 2 nd Quarter Level
D2: Theoretical Exam | E2: Practical Exam | F2: Total | G2: Assessment | H2: Grand Total | I2: Theoretical Exam | J2: Practical Exam | K2: Total | L2: Assessment | M2: Grand Total
A3: 1 | B3: EBRAHIM NASSER ABDULLAH ALSAGER | C3: 4A | D3: 7 | E3: 10 | F3: =SUM(D3:E3) -> 17 | G3: 22.5 | H3: =SUM(F3:G3) -> 39.5 | K3: =SUM(Result2!$I3:$J3) -> 0 | M3: =SUM(Result2!$K3:$L3) -> 0 | N3: =IF(Result2!$H3>40,"ON LEVEL", IF(Result2!$H3>30,"APPROACH", "BELOW LEVEL")) -> APPROACH | O3: =IF(Result2!$M3>40,"ONLEVEL", IF(Result2!$M3>20,"APPROACH", "BELOW LEVEL")) -> BELOW LEVEL
A4: 2 | B4: SAIF KHALID MOHAMMED ALAFALIQ | C4: 4A | D4: 8.5 | E4: 10 | F4: =SUM(D4:E4) -> 18.5 | G4: 27.5 | H4: =SUM(F4:G4) -> 46 | K4: =SUM(Result2!$I4:$J4) -> 0 | M4: =SUM(Result2!$K4:$L4) -> 0 | N4: =IF(Result2!$H4>40,"ON LEVEL", IF(Result2!$H4>30,"APPROACH", "BELOW LEVEL")) -> ON LEVEL | O4: =IF(Result2!$M4>40,"ONLEVEL", IF(Result2!$M4>20,"APPROACH", "BELOW LEVEL")) -> BELOW LEVEL
A5: 3 | B5: ABBAS ALAA HASSAN AL AITHAN | C5: 4A | D5: 8.5 | E5: 10 | F5: =SUM(D5:E5) -> 18.5 | G5: 26.5 | H5: =SUM(F5:G5) -> 45 | K5: =SUM(Result2!$I5:$J5) -> 0 | M5: =SUM(Result2!$K5:$L5) -> 0 | N5: =IF(Result2!$H5>40,"ON LEVEL", IF(Result2!$H5>30,"APPROACH", "BELOW LEVEL")) -> ON LEVEL | O5: =IF(Result2!$M5>40,"ONLEVEL", IF(Result2!$M5>20,"APPROACH", "BELOW LEVEL")) -> BELOW LEVEL
A6: 4 | B6: ABDULRAHMAN FAHAD ABDULRAHMAN ALJAMAAN | C6: 4A | D6: 7 | E6: 10 | F6: =SUM(D6:E6) -> 17 | G6: 24.5 | H6: =SUM(F6:G6) -> 41.5 | K6: =SUM(Result2!$I6:$J6) -> 0 | M6: =SUM(Result2!$K6:$L6) -> 0 | N6: =IF(Result2!$H6>40,"ON LEVEL", IF(Result2!$H6>30,"APPROACH", "BELOW LEVEL")) -> ON LEVEL | O6: =IF(Result2!$M6>40,"ONLEVEL", IF(Result2!$M6>20,"APPROACH", "BELOW LEVEL")) -> BELOW LEVEL
A7: 5 | B7: Abdullah Abdulmajid Alarfaj | C7: 4A | D7: 10 | E7: 10 | F7: =SUM(D7:E7) -> 20 | G7: 28 | H7: =SUM(F7:G7) -> 48 | K7: =SUM(Result2!$I7:$J7) -> 0 | M7: =SUM(Result2!$K7:$L7) -> 0 | N7: =IF(Result2!$H7>40,"ON LEVEL", IF(Result2!$H7>30,"APPROACH", "BELOW LEVEL")) -> ON LEVEL | O7: =IF(Result2!$M7>40,"ONLEVEL", IF(Result2!$M7>20,"APPROACH", "BELOW LEVEL")) -> BELOW LEVEL
A8: 6 | B8: OMAR SHADI MOHAMMAD QAWAQNEH | C8: 4A | D8: 9.5 | E8: 10 | F8: =SUM(D8:E8) -> 19.5 | G8: 27.5 | H8: =SUM(F8:G8) -> 47 | K8: =SUM(Result2!$I8:$J8) -> 0 | M8: =SUM(Result2!$K8:$L8) -> 0 | N8: =IF(Result2!$H8>40,"ON LEVEL", IF(Result2!$H8>30,"APPROACH", "BELOW LEVEL")) -> ON LEVEL | O8: =IF(Result2!$M8>40,"ONLEVEL", IF(Result2!$M8>20,"APPROACH", "BELOW LEVEL")) -> BELOW LEVEL
A9: 7 | B9: FAISAL ABDULMOHSEN ABDULAZIZ ALMULHEM | C9: 4A | D9: 9 | E9: 10 | F9: =SUM(D9:E9) -> 19 | G9: 29 | H9: =SUM(F9:G9) -> 48 | K9: =SUM(Result2!$I9:$J9) -> 0 | M9: =SUM(Result2!$K9:$L9) -> 0 | N9: =IF(Result2!$H9>40,"ON LEVEL", IF(Result2!$H9>30,"APPROACH", "BELOW LEVEL")) -> ON LEVEL | O9: =IF(Result2!$M9>40,"ONLEVEL", IF(Result2!$M9>20,"APPROACH", "BELOW LEVEL")) -> BELOW LEVEL
A10: 8 | B10: MOHAMMED AHMED YOUSIF ALYOUSIF | C10: 4A | D10: 9 | E10: 10 | F10: =SUM(D10:E10) -> 19 | G10: 23 | H10: =SUM(F10:G10) -> 42 | K10: =SUM(Result2!$I10:$J10) -> 0 | M10: =SUM(Result2!$K10:$L10) -> 0 | N10: =IF(Result2!$H10>40,"ON LEVEL", IF(Result2!$H10>30,"APPROACH", "BELOW LEVEL")) -> ON LEVEL | O10: =IF(Result2!$M10>40,"ONLEVEL", IF(Result2!$M10>20,"APPROACH", "BELOW LEVEL")) -> BELOW LEVEL
A11: 9 | B11: YOUSIF AHMED ABDULLMAJEED ALHAJII | C11: 4A | D11: 9 | E11: 10 | F11: =SUM(D11:E11) -> 19 | G11: 29.5 | H11: =SUM(F11:G11) -> 48.5 | K11: =SUM(Result2!$I11:$J11) -> 0 | M11: =SUM(Result2!$K11:$L11) -> 0 | N11: =IF(Result2!$H11>40,"ON LEVEL", IF(Result2!$H11>30,"APPROACH", "BELOW LEVEL")) -> ON LEVEL | O11: =IF(Result2!$M11>40,"ONLEVEL", IF(Result2!$M11>20,"APPROACH", "BELOW LEVEL")) -> BELOW LEVEL
A12: 10 | B12: ABDULAZIZ FAHAD ABDULAZIZ ALMULHIM | C12: 4A | D12: 9 | E12: 10 | F12: =SUM(D12:E12) -> 19 | G12: 27.5 | H12: =SUM(F12:G12) -> 46.5 | K12: =SUM(Result2!$I12:$J12) -> 0 | M12: =SUM(Result2!$K12:$L12) -> 0 | N12: =IF(Result2!$H12>40,"ON LEVEL", IF(Result2!$H12>30,"APPROACH", "BELOW LEVEL")) -> ON LEVEL | O12: =IF(Result2!$M12>40,"ONLEVEL", IF(Result2!$M12>20,"APPROACH", "BELOW LEVEL")) -> BELOW LEVEL
A13: 11 | B13: Ali Hussain Alhassan | C13: 4A | D13: 10 | E13: 10 | F13: =SUM(D13:E13) -> 20 | G13: 27.5 | H13: =SUM(F13:G13) -> 47.5 | K13: =SUM(Result2!$I13:$J13) -> 0 | M13: =SUM(Result2!$K13:$L13) -> 0 | N13: =IF(Result2!$H13>40,"ON LEVEL", IF(Result2!$H13>30,"APPROACH", "BELOW LEVEL")) -> ON LEVEL | O13: =IF(Result2!$M13>40,"ONLEVEL", IF(Result2!$M13>20,"APPROACH", "BELOW LEVEL")) -> BELOW LEVEL
A14: 12 | B14: Khalid Mohammed Yousef Almulhim | C14: 4A | D14: 10 | E14: 10 | F14: =SUM(D14:E14) -> 20 | G14: 29.5 | H14: =SUM(F14:G14) -> 49.5 | K14: =SUM(Result2!$I14:$J14) -> 0 | M14: =SUM(Result2!$K14:$L14) -> 0 | N14: =IF(Result2!$H14>40,"ON LEVEL", IF(Result2!$H14>30,"APPROACH", "BELOW LEVEL")) -> ON LEVEL | O14: =IF(Result2!$M14>40,"ONLEVEL", IF(Result2!$M14>20,"APPROACH", "BELOW LEVEL")) -> BELOW LEVEL
... A110: 108 | B110: Ibrahim Abdullah Ibrahim Al Jouf | C110: 6B | D110: 8 | E110: 10 | F110: =SUM(D110:E110) -> 18 | G110: 28.5 | H110: =SUM(F110:G110) -> 46.5 | K110: =SUM(Result2!$I110:$J110) -> 0 | M110: =SUM(Result2!$K110:$L110) -> 0 | N110: =IF(Result2!$H110>40,"ON LEVEL", IF(Result2!$H110>30,"APPROACH", "BELOW LEVEL")) -> ON LEVEL | O110: =IF(Result2!$M110>40,"ONLEVEL", IF(Result2!$M110>20,"APPROACH", "BELOW LEVEL")) -> BELOW LEVEL

Sheet Findings &DiscussionTerm1
H3: Data analysis Meeting
E4: Interpretations of the root cause of your findings and your theory of action
B6: Grade | C6: Computer
B7: Dear Mr. I would like to meet you individually to discuss the results of the 1st semester exam. The meeting will be held on --------------. Please be prepared to discuss the following points
B12: No. | C12: Topic for discussion
B13: 1 | C13: How do you feel about your students’ performance?
B22: 2 | C22: What part of data caught your attention?
B29: 3 | C29: What actions can be based on your insights about this analyzed data?
B33: 4 | C33: What do you recommend to enhance the performance of your students?
N39: ملاحظة : يرجى الاجابة جيدا على الأسئلة تمهيدا لمناقشتها مع المشرف ، هدف الاسئلة هو تدريب المعلم على قراءة البيانات وتفسيرها ، وإيجاد نقاط التحسين .
N40: الخطط العلاجية سوف توضع بناء على نتائج المناقشة ، يرجى ذكر مجال التحسين (Area) كذكر الكتابة أو القواعد ، وتحديد الفصل الدراسي مع ذكر الأسباب .
